[2023-01-06 15:17:48,678] {taskinstance.py:1159} INFO - Dependencies all met for <TaskInstance: EL.Load_data manual__2023-01-06T15:17:43.182924+00:00 [queued]>
[2023-01-06 15:17:48,687] {taskinstance.py:1159} INFO - Dependencies all met for <TaskInstance: EL.Load_data manual__2023-01-06T15:17:43.182924+00:00 [queued]>
[2023-01-06 15:17:48,687] {taskinstance.py:1356} INFO - 
--------------------------------------------------------------------------------
[2023-01-06 15:17:48,688] {taskinstance.py:1357} INFO - Starting attempt 1 of 1
[2023-01-06 15:17:48,688] {taskinstance.py:1358} INFO - 
--------------------------------------------------------------------------------
[2023-01-06 15:17:48,702] {taskinstance.py:1377} INFO - Executing <Task(PythonOperator): Load_data> on 2023-01-06 15:17:43.182924+00:00
[2023-01-06 15:17:48,706] {standard_task_runner.py:52} INFO - Started process 595 to run task
[2023-01-06 15:17:48,709] {standard_task_runner.py:79} INFO - Running: ['airflow', 'tasks', 'run', 'EL', 'Load_data', 'manual__2023-01-06T15:17:43.182924+00:00', '--job-id', '15', '--raw', '--subdir', 'DAGS_FOLDER/test_dag.py', '--cfg-path', '/tmp/tmpc3xvxlmn', '--error-file', '/tmp/tmp59v5van3']
[2023-01-06 15:17:48,709] {standard_task_runner.py:80} INFO - Job 15: Subtask Load_data
[2023-01-06 15:17:48,751] {task_command.py:369} INFO - Running <TaskInstance: EL.Load_data manual__2023-01-06T15:17:43.182924+00:00 [running]> on host dcfdc2efb79e
[2023-01-06 15:17:48,804] {taskinstance.py:1571} INFO - Exporting the following env vars:
AIRFLOW_CTX_DAG_OWNER=airflow
AIRFLOW_CTX_DAG_ID=EL
AIRFLOW_CTX_TASK_ID=Load_data
AIRFLOW_CTX_EXECUTION_DATE=2023-01-06T15:17:43.182924+00:00
AIRFLOW_CTX_TRY_NUMBER=1
AIRFLOW_CTX_DAG_RUN_ID=manual__2023-01-06T15:17:43.182924+00:00
[2023-01-06 15:17:48,805] {logging_mixin.py:115} INFO - Connecting to db
[2023-01-06 15:17:48,806] {taskinstance.py:1889} ERROR - Task failed with exception
Traceback (most recent call last):
  File "/home/airflow/.local/lib/python3.7/site-packages/airflow/operators/python.py", line 171, in execute
    return_value = self.execute_callable()
  File "/home/airflow/.local/lib/python3.7/site-packages/airflow/operators/python.py", line 189, in execute_callable
    return self.python_callable(*self.op_args, **self.op_kwargs)
  File "/opt/airflow/dags/test_dag.py", line 49, in loadData
    conn = psycopg2.connect(conn_string)
  File "/home/airflow/.local/lib/python3.7/site-packages/psycopg2/__init__.py", line 122, in connect
    conn = _connect(dsn, connection_factory=connection_factory, **kwasync)
psycopg2.OperationalError: connection to server at "localhost" (127.0.0.1), port 5432 failed: Connection refused
	Is the server running on that host and accepting TCP/IP connections?
connection to server at "localhost" (::1), port 5432 failed: Cannot assign requested address
	Is the server running on that host and accepting TCP/IP connections?

[2023-01-06 15:17:48,817] {taskinstance.py:1400} INFO - Marking task as FAILED. dag_id=EL, task_id=Load_data, execution_date=20230106T151743, start_date=20230106T151748, end_date=20230106T151748
[2023-01-06 15:17:48,828] {standard_task_runner.py:97} ERROR - Failed to execute job 15 for task Load_data (connection to server at "localhost" (127.0.0.1), port 5432 failed: Connection refused
	Is the server running on that host and accepting TCP/IP connections?
connection to server at "localhost" (::1), port 5432 failed: Cannot assign requested address
	Is the server running on that host and accepting TCP/IP connections?
; 595)
[2023-01-06 15:17:48,841] {local_task_job.py:156} INFO - Task exited with return code 1
[2023-01-06 15:17:48,869] {local_task_job.py:273} INFO - 0 downstream tasks scheduled from follow-on schedule check
