[2023-01-06 15:13:17,705] {taskinstance.py:1159} INFO - Dependencies all met for <TaskInstance: EL.Get_data manual__2023-01-06T15:13:15.776290+00:00 [queued]>
[2023-01-06 15:13:17,712] {taskinstance.py:1159} INFO - Dependencies all met for <TaskInstance: EL.Get_data manual__2023-01-06T15:13:15.776290+00:00 [queued]>
[2023-01-06 15:13:17,713] {taskinstance.py:1356} INFO - 
--------------------------------------------------------------------------------
[2023-01-06 15:13:17,713] {taskinstance.py:1357} INFO - Starting attempt 1 of 1
[2023-01-06 15:13:17,714] {taskinstance.py:1358} INFO - 
--------------------------------------------------------------------------------
[2023-01-06 15:13:17,728] {taskinstance.py:1377} INFO - Executing <Task(PythonOperator): Get_data> on 2023-01-06 15:13:15.776290+00:00
[2023-01-06 15:13:17,733] {standard_task_runner.py:52} INFO - Started process 361 to run task
[2023-01-06 15:13:17,735] {standard_task_runner.py:79} INFO - Running: ['airflow', 'tasks', 'run', 'EL', 'Get_data', 'manual__2023-01-06T15:13:15.776290+00:00', '--job-id', '6', '--raw', '--subdir', 'DAGS_FOLDER/test_dag.py', '--cfg-path', '/tmp/tmpmnm8p1u4', '--error-file', '/tmp/tmpr6b7nyo5']
[2023-01-06 15:13:17,736] {standard_task_runner.py:80} INFO - Job 6: Subtask Get_data
[2023-01-06 15:13:17,779] {task_command.py:369} INFO - Running <TaskInstance: EL.Get_data manual__2023-01-06T15:13:15.776290+00:00 [running]> on host dcfdc2efb79e
[2023-01-06 15:13:17,838] {taskinstance.py:1571} INFO - Exporting the following env vars:
AIRFLOW_CTX_DAG_OWNER=airflow
AIRFLOW_CTX_DAG_ID=EL
AIRFLOW_CTX_TASK_ID=Get_data
AIRFLOW_CTX_EXECUTION_DATE=2023-01-06T15:13:15.776290+00:00
AIRFLOW_CTX_TRY_NUMBER=1
AIRFLOW_CTX_DAG_RUN_ID=manual__2023-01-06T15:13:15.776290+00:00
[2023-01-06 15:13:20,318] {taskinstance.py:1889} ERROR - Task failed with exception
Traceback (most recent call last):
  File "/home/airflow/.local/lib/python3.7/site-packages/airflow/operators/python.py", line 171, in execute
    return_value = self.execute_callable()
  File "/home/airflow/.local/lib/python3.7/site-packages/airflow/operators/python.py", line 189, in execute_callable
    return self.python_callable(*self.op_args, **self.op_kwargs)
  File "/opt/airflow/dags/test_dag.py", line 20, in extractData
    year, month, day = date.split('-')
AttributeError: 'dict' object has no attribute 'split'
[2023-01-06 15:13:20,334] {taskinstance.py:1400} INFO - Marking task as FAILED. dag_id=EL, task_id=Get_data, execution_date=20230106T151315, start_date=20230106T151317, end_date=20230106T151320
[2023-01-06 15:13:20,349] {standard_task_runner.py:97} ERROR - Failed to execute job 6 for task Get_data ('dict' object has no attribute 'split'; 361)
[2023-01-06 15:13:20,396] {local_task_job.py:156} INFO - Task exited with return code 1
[2023-01-06 15:13:20,441] {local_task_job.py:273} INFO - 0 downstream tasks scheduled from follow-on schedule check
