[2023-01-06 12:39:00,976] {taskinstance.py:1159} INFO - Dependencies all met for <TaskInstance: Demo.Dag_Test scheduled__2023-01-06T12:38:00+00:00 [queued]>
[2023-01-06 12:39:00,986] {taskinstance.py:1159} INFO - Dependencies all met for <TaskInstance: Demo.Dag_Test scheduled__2023-01-06T12:38:00+00:00 [queued]>
[2023-01-06 12:39:00,986] {taskinstance.py:1356} INFO - 
--------------------------------------------------------------------------------
[2023-01-06 12:39:00,987] {taskinstance.py:1357} INFO - Starting attempt 1 of 1
[2023-01-06 12:39:00,987] {taskinstance.py:1358} INFO - 
--------------------------------------------------------------------------------
[2023-01-06 12:39:01,002] {taskinstance.py:1377} INFO - Executing <Task(BashOperator): Dag_Test> on 2023-01-06 12:38:00+00:00
[2023-01-06 12:39:01,007] {standard_task_runner.py:52} INFO - Started process 8126 to run task
[2023-01-06 12:39:01,010] {standard_task_runner.py:79} INFO - Running: ['airflow', 'tasks', 'run', 'Demo', 'Dag_Test', 'scheduled__2023-01-06T12:38:00+00:00', '--job-id', '8', '--raw', '--subdir', 'DAGS_FOLDER/demonstration.py', '--cfg-path', '/tmp/tmp8ngeg749', '--error-file', '/tmp/tmpu5m7vyzt']
[2023-01-06 12:39:01,011] {standard_task_runner.py:80} INFO - Job 8: Subtask Dag_Test
[2023-01-06 12:39:01,058] {task_command.py:369} INFO - Running <TaskInstance: Demo.Dag_Test scheduled__2023-01-06T12:38:00+00:00 [running]> on host 6ef47e34797a
[2023-01-06 12:39:01,117] {taskinstance.py:1571} INFO - Exporting the following env vars:
AIRFLOW_CTX_DAG_OWNER=airflow
AIRFLOW_CTX_DAG_ID=Demo
AIRFLOW_CTX_TASK_ID=Dag_Test
AIRFLOW_CTX_EXECUTION_DATE=2023-01-06T12:38:00+00:00
AIRFLOW_CTX_TRY_NUMBER=1
AIRFLOW_CTX_DAG_RUN_ID=scheduled__2023-01-06T12:38:00+00:00
[2023-01-06 12:39:01,118] {subprocess.py:62} INFO - Tmp dir root location: 
 /tmp
[2023-01-06 12:39:01,119] {subprocess.py:74} INFO - Running command: ['bash', '-c', <function helloDag at 0x7f14120634d0>]
[2023-01-06 12:39:01,119] {taskinstance.py:1889} ERROR - Task failed with exception
Traceback (most recent call last):
  File "/home/airflow/.local/lib/python3.7/site-packages/airflow/operators/bash.py", line 189, in execute
    cwd=self.cwd,
  File "/home/airflow/.local/lib/python3.7/site-packages/airflow/hooks/subprocess.py", line 82, in run_command
    preexec_fn=pre_exec,
  File "/usr/local/lib/python3.7/subprocess.py", line 800, in __init__
    restore_signals, start_new_session)
  File "/usr/local/lib/python3.7/subprocess.py", line 1482, in _execute_child
    restore_signals, start_new_session, preexec_fn)
TypeError: expected str, bytes or os.PathLike object, not function
[2023-01-06 12:39:01,127] {taskinstance.py:1400} INFO - Marking task as FAILED. dag_id=Demo, task_id=Dag_Test, execution_date=20230106T123800, start_date=20230106T123900, end_date=20230106T123901
[2023-01-06 12:39:01,137] {standard_task_runner.py:97} ERROR - Failed to execute job 8 for task Dag_Test (expected str, bytes or os.PathLike object, not function; 8126)
[2023-01-06 12:39:01,182] {local_task_job.py:156} INFO - Task exited with return code 1
[2023-01-06 12:39:01,208] {local_task_job.py:273} INFO - 0 downstream tasks scheduled from follow-on schedule check
