[2023-01-06 15:09:22,301] {taskinstance.py:1159} INFO - Dependencies all met for <TaskInstance: EL.Get_data manual__2023-01-06T15:09:20.039327+00:00 [queued]>
[2023-01-06 15:09:22,314] {taskinstance.py:1159} INFO - Dependencies all met for <TaskInstance: EL.Get_data manual__2023-01-06T15:09:20.039327+00:00 [queued]>
[2023-01-06 15:09:22,315] {taskinstance.py:1356} INFO - 
--------------------------------------------------------------------------------
[2023-01-06 15:09:22,315] {taskinstance.py:1357} INFO - Starting attempt 1 of 1
[2023-01-06 15:09:22,316] {taskinstance.py:1358} INFO - 
--------------------------------------------------------------------------------
[2023-01-06 15:09:22,336] {taskinstance.py:1377} INFO - Executing <Task(PythonOperator): Get_data> on 2023-01-06 15:09:20.039327+00:00
[2023-01-06 15:09:22,343] {standard_task_runner.py:52} INFO - Started process 184 to run task
[2023-01-06 15:09:22,347] {standard_task_runner.py:79} INFO - Running: ['airflow', 'tasks', 'run', 'EL', 'Get_data', 'manual__2023-01-06T15:09:20.039327+00:00', '--job-id', '4', '--raw', '--subdir', 'DAGS_FOLDER/test_dag.py', '--cfg-path', '/tmp/tmpiwg23b3x', '--error-file', '/tmp/tmpz933kbnf']
[2023-01-06 15:09:22,348] {standard_task_runner.py:80} INFO - Job 4: Subtask Get_data
[2023-01-06 15:09:22,419] {task_command.py:369} INFO - Running <TaskInstance: EL.Get_data manual__2023-01-06T15:09:20.039327+00:00 [running]> on host dcfdc2efb79e
[2023-01-06 15:09:22,494] {taskinstance.py:1571} INFO - Exporting the following env vars:
AIRFLOW_CTX_DAG_OWNER=airflow
AIRFLOW_CTX_DAG_ID=EL
AIRFLOW_CTX_TASK_ID=Get_data
AIRFLOW_CTX_EXECUTION_DATE=2023-01-06T15:09:20.039327+00:00
AIRFLOW_CTX_TRY_NUMBER=1
AIRFLOW_CTX_DAG_RUN_ID=manual__2023-01-06T15:09:20.039327+00:00
[2023-01-06 15:09:22,495] {taskinstance.py:1889} ERROR - Task failed with exception
Traceback (most recent call last):
  File "/home/airflow/.local/lib/python3.7/site-packages/airflow/operators/python.py", line 171, in execute
    return_value = self.execute_callable()
  File "/home/airflow/.local/lib/python3.7/site-packages/airflow/operators/python.py", line 189, in execute_callable
    return self.python_callable(*self.op_args, **self.op_kwargs)
  File "/opt/airflow/dags/test_dag.py", line 19, in extractData
    for date in dates:
TypeError: 'PythonOperator' object is not iterable
[2023-01-06 15:09:22,517] {taskinstance.py:1400} INFO - Marking task as FAILED. dag_id=EL, task_id=Get_data, execution_date=20230106T150920, start_date=20230106T150922, end_date=20230106T150922
[2023-01-06 15:09:22,532] {standard_task_runner.py:97} ERROR - Failed to execute job 4 for task Get_data ('PythonOperator' object is not iterable; 184)
[2023-01-06 15:09:22,560] {local_task_job.py:156} INFO - Task exited with return code 1
[2023-01-06 15:09:22,597] {local_task_job.py:273} INFO - 0 downstream tasks scheduled from follow-on schedule check
