[2023-01-06 15:16:56,143] {taskinstance.py:1159} INFO - Dependencies all met for <TaskInstance: EL.Get_data manual__2023-01-06T15:16:53.633305+00:00 [queued]>
[2023-01-06 15:16:56,152] {taskinstance.py:1159} INFO - Dependencies all met for <TaskInstance: EL.Get_data manual__2023-01-06T15:16:53.633305+00:00 [queued]>
[2023-01-06 15:16:56,153] {taskinstance.py:1356} INFO - 
--------------------------------------------------------------------------------
[2023-01-06 15:16:56,154] {taskinstance.py:1357} INFO - Starting attempt 1 of 1
[2023-01-06 15:16:56,154] {taskinstance.py:1358} INFO - 
--------------------------------------------------------------------------------
[2023-01-06 15:16:56,168] {taskinstance.py:1377} INFO - Executing <Task(PythonOperator): Get_data> on 2023-01-06 15:16:53.633305+00:00
[2023-01-06 15:16:56,173] {standard_task_runner.py:52} INFO - Started process 544 to run task
[2023-01-06 15:16:56,176] {standard_task_runner.py:79} INFO - Running: ['airflow', 'tasks', 'run', 'EL', 'Get_data', 'manual__2023-01-06T15:16:53.633305+00:00', '--job-id', '12', '--raw', '--subdir', 'DAGS_FOLDER/test_dag.py', '--cfg-path', '/tmp/tmpkzqucr2v', '--error-file', '/tmp/tmpjd4v5k9i']
[2023-01-06 15:16:56,177] {standard_task_runner.py:80} INFO - Job 12: Subtask Get_data
[2023-01-06 15:16:56,225] {task_command.py:369} INFO - Running <TaskInstance: EL.Get_data manual__2023-01-06T15:16:53.633305+00:00 [running]> on host dcfdc2efb79e
[2023-01-06 15:16:56,282] {taskinstance.py:1571} INFO - Exporting the following env vars:
AIRFLOW_CTX_DAG_OWNER=airflow
AIRFLOW_CTX_DAG_ID=EL
AIRFLOW_CTX_TASK_ID=Get_data
AIRFLOW_CTX_EXECUTION_DATE=2023-01-06T15:16:53.633305+00:00
AIRFLOW_CTX_TRY_NUMBER=1
AIRFLOW_CTX_DAG_RUN_ID=manual__2023-01-06T15:16:53.633305+00:00
[2023-01-06 15:16:56,283] {logging_mixin.py:115} INFO - 2023-01-06
[2023-01-06 15:16:56,891] {taskinstance.py:1889} ERROR - Task failed with exception
Traceback (most recent call last):
  File "/home/airflow/.local/lib/python3.7/site-packages/airflow/operators/python.py", line 171, in execute
    return_value = self.execute_callable()
  File "/home/airflow/.local/lib/python3.7/site-packages/airflow/operators/python.py", line 189, in execute_callable
    return self.python_callable(*self.op_args, **self.op_kwargs)
  File "/opt/airflow/dags/test_dag.py", line 40, in extractData
    data_list.append(data_dict)
NameError: name 'data_list' is not defined
[2023-01-06 15:16:56,903] {taskinstance.py:1400} INFO - Marking task as FAILED. dag_id=EL, task_id=Get_data, execution_date=20230106T151653, start_date=20230106T151656, end_date=20230106T151656
[2023-01-06 15:16:57,064] {standard_task_runner.py:97} ERROR - Failed to execute job 12 for task Get_data (name 'data_list' is not defined; 544)
[2023-01-06 15:16:57,071] {local_task_job.py:156} INFO - Task exited with return code 1
[2023-01-06 15:16:57,106] {local_task_job.py:273} INFO - 0 downstream tasks scheduled from follow-on schedule check
